version: '3.7'
# Removed subprocess.CalledProcessError: Command '['/usr/local/bin/docker-credential-desktop', 'get']' returned non-zero exit status 1
# I had this:
# cat ~/.docker/config.json
# {"auths":{},"credsStore":"", "credsStore":"desktop","stackOrchestrator":"swarm"}
# I updated to this:
# {"auths":{},"credsStore":"","stackOrchestrator":"swarm"}
services:
  product-management-compose:
    image: product-management-compose
    #build:
      #context: .
      #dockerfile: Dockerfile
    ports:
      - "8080:8080"
    depends_on: # Start the depends_on first
      - myapp 
    
    environment:
      - DATABASE_HOST=myapp
      - DATABASE_USER=test
      - DATABASE_PASSWORD=root
      - DATABASE_NAME=fullstack
      - DATABASE_PORT=3306
    networks:
      - todo-web-application-network

  myapp:
    image: mysql:5.7
    ports:
      - "3306:3306"
    restart: always
    environment:
      MYSQL_ROOT_PASSWORD: root
      MYSQL_USER: test
      MYSQL_PASSWORD: root
      MYSQL_DATABASE: fullstack
    volumes:
      - mysql-database-data-volume:/var/lib/mysql
    networks:
      - todo-web-application-network  
  
# Volumes
volumes:
  mysql-database-data-volume:

networks:
  todo-web-application-network: